<?xml version="1.0" ?>
<!-- =================================================================================== -->
<!-- |    This document was autogenerated by xacro from /home/taiga/ros2_ws/install/gentact_descriptions/share/gentact_descriptions/robots/fr3/fr3_hybrid_skin.xacro | -->
<!-- |    EDITING THIS FILE BY HAND IS NOT RECOMMENDED                                 | -->
<!-- =================================================================================== -->
<robot name="fr3">
  <!-- <xacro:arg name="ee_xacro_file" default=""/> -->
  <!-- safety_distance: Minimum safety distance in [m] by which the collision volumes are expanded and which is enforced during robot motions -->
  <!-- arm_id: Namespace of the robot arm. Serves to differentiate between arms in case of multiple instances. -->
  <!-- joint_limits: description of the joint limits that comes from a YAML file. Example definition: ${xacro.load_yaml('$(find gentact_descriptions)/robots/fr3/joint_limits.yaml')} -->
  <!-- kinematics: description of the kinematics that comes from a YAML file. Example definition: ${xacro.load_yaml('$(find gentact_descriptions)/robots/fr3/kinematics.yaml')} -->
  <!-- inertials: description of the inertials that comes from a YAML file. Example definition: ${xacro.load_yaml('$(find gentact_descriptions)/robots/fr3/inertials.yaml')} -->
  <!-- dynamics: description of the dynamics that comes from a YAML file. Example definition: ${xacro.load_yaml('$(find gentact_descriptions)/robots/fr3/dynamics.yaml')} -->
  <link name="base">
      </link>
  <joint name="fr3_base_joint" type="fixed">
    <parent link="base"/>
    <child link="fr3_link0"/>
    <origin rpy="0 0 0" xyz="0 0 0"/>
  </joint>
  <!-- sub-link defining detailed meshes for collision with environment -->
  <link name="fr3_link0">
    <visual name="fr3_link0_visual">
      <geometry>
        <mesh filename="package://gentact_descriptions/meshes/robot_arms/fr3/visual/link0.dae"/>
      </geometry>
    </visual>
    <collision name="fr3_link0_collision">
      <geometry>
        <mesh filename="package://gentact_descriptions/meshes/robot_arms/fr3/collision/link0.stl"/>
      </geometry>
    </collision>
    <inertial>
      <origin rpy="0 0 0" xyz="-0.0172 0.0004 0.0745"/>
      <mass value="2.3966"/>
      <inertia ixx="0.009" ixy="0.0" ixz="0.002" iyy="0.0115" iyz="0.0" izz="0.0085"/>
    </inertial>
  </link>
  <!-- sub-link defining detailed meshes for collision with environment -->
  <link name="fr3_link1">
    <visual name="fr3_link1_visual">
      <geometry>
        <mesh filename="package://gentact_descriptions/meshes/robot_arms/fr3/visual/link1.dae"/>
      </geometry>
    </visual>
    <collision name="fr3_link1_collision">
      <geometry>
        <mesh filename="package://gentact_descriptions/meshes/robot_arms/fr3/collision/link1.stl"/>
      </geometry>
    </collision>
    <inertial>
      <origin rpy="0 0 0" xyz="0.0000004128 -0.0181251324 -0.0386035970"/>
      <mass value="2.9274653454"/>
      <inertia ixx="0.023927316485107913" ixy="1.3317903455714081e-05" ixz="-0.00011404774918616684" iyy="0.0224821613275756" iyz="-0.0019950320628240115" izz="0.006350098258530016"/>
    </inertial>
  </link>
  <joint name="fr3_joint1" type="revolute">
    <origin rpy="0 0 0" xyz="0 0 0.333"/>
    <parent link="fr3_link0"/>
    <child link="fr3_link1"/>
    <axis xyz="0 0 1"/>
    <limit effort="87.0" lower="-2.7437" upper="2.7437" velocity="2.62"/>
    <safety_controller k_position="100.0" k_velocity="40.0" soft_lower_limit="-2.7437" soft_upper_limit="2.7437"/>
    <dynamics D="1" K="7000" damping="0.003" friction="0.2" mu_coulomb="0" mu_viscous="16"/>
  </joint>
  <!-- sub-link defining detailed meshes for collision with environment -->
  <link name="fr3_link2">
    <visual name="fr3_link2_visual">
      <geometry>
        <mesh filename="package://gentact_descriptions/meshes/robot_arms/fr3/visual/link2.dae"/>
      </geometry>
    </visual>
    <collision name="fr3_link2_collision">
      <geometry>
        <mesh filename="package://gentact_descriptions/meshes/robot_arms/fr3/collision/link2.stl"/>
      </geometry>
    </collision>
    <inertial>
      <origin rpy="0 0 0" xyz="0.0031828864 -0.0743221644 0.0088146084"/>
      <mass value="2.9355370338"/>
      <inertia ixx="0.041938946257609425" ixy="0.00020257331521090626" ixz="0.004077784227179924" iyy="0.02514514885014724" iyz="-0.0042252158006570156" izz="0.06170214472888839"/>
    </inertial>
  </link>
  <joint name="fr3_joint2" type="revolute">
    <origin rpy="-1.570796326794897 0 0" xyz="0 0 0"/>
    <parent link="fr3_link1"/>
    <child link="fr3_link2"/>
    <axis xyz="0 0 1"/>
    <limit effort="87.0" lower="-1.7837" upper="1.7837" velocity="2.62"/>
    <safety_controller k_position="100.0" k_velocity="40.0" soft_lower_limit="-1.7837" soft_upper_limit="1.7837"/>
    <dynamics D="1" K="7000" damping="0.003" friction="0.2" mu_coulomb="0" mu_viscous="16"/>
  </joint>
  <!-- [m] -->
  <link name="link2_skin">
    <visual>
      <origin rpy="0 0 0" xyz="0 0 0"/>
      <geometry>
        <!--loool the scale is totally different dude-->
        <mesh filename="package://gentact_descriptions/meshes/skin/hybrid/link2_hybrid_dermis.stl" scale="0.001 0.001 0.001"/>
      </geometry>
    </visual>
  </link>
  <joint name="link2_base_joint" type="fixed">
    <origin rpy="-1.5707 0 0" xyz="0 0 0"/>
    <parent link="fr3_link2"/>
    <child link="link2_skin"/>
  </joint>
  <joint name="link2_sensor_0_joint" type="fixed">
    <origin rpy="1.627 -0.000 2.332" xyz="0.052 0.111 -0.004"/>
    <axis xyz="0.723 0.688 -0.056"/>
    <parent link="link2_skin"/>
    <child link="link2_sensor_0"/>
  </joint>
  <link name="link2_sensor_0">
  </link>
  <joint name="link2_sensor_1_joint" type="fixed">
    <origin rpy="0.893 0.000 2.514" xyz="0.029 0.112 0.042"/>
    <axis xyz="0.458 0.631 0.627"/>
    <parent link="link2_skin"/>
    <child link="link2_sensor_1"/>
  </joint>
  <link name="link2_sensor_1">
  </link>
  <joint name="link2_sensor_2_joint" type="fixed">
    <origin rpy="-1.463 -3.142 -0.106" xyz="0.007 0.136 -0.007"/>
    <axis xyz="0.106 0.989 -0.108"/>
    <parent link="link2_skin"/>
    <child link="link2_sensor_2"/>
  </joint>
  <link name="link2_sensor_2">
  </link>
  <joint name="link2_sensor_3_joint" type="fixed">
    <origin rpy="1.466 0.000 2.917" xyz="0.009 0.064 0.131"/>
    <axis xyz="0.222 0.969 0.105"/>
    <parent link="link2_skin"/>
    <child link="link2_sensor_3"/>
  </joint>
  <link name="link2_sensor_3">
  </link>
  <joint name="link2_sensor_4_joint" type="fixed">
    <origin rpy="-0.668 -3.142 0.217" xyz="-0.009 0.112 -0.051"/>
    <axis xyz="-0.133 0.605 -0.785"/>
    <parent link="link2_skin"/>
    <child link="link2_sensor_4"/>
  </joint>
  <link name="link2_sensor_4">
  </link>
  <joint name="link2_sensor_5_joint" type="fixed">
    <origin rpy="0.869 -0.000 -2.678" xyz="-0.024 0.113 0.045"/>
    <axis xyz="-0.341 0.683 0.646"/>
    <parent link="link2_skin"/>
    <child link="link2_sensor_5"/>
  </joint>
  <link name="link2_sensor_5">
  </link>
  <joint name="link2_sensor_6_joint" type="fixed">
    <origin rpy="1.630 -0.000 -2.249" xyz="-0.050 0.113 -0.009"/>
    <axis xyz="-0.777 0.627 -0.06"/>
    <parent link="link2_skin"/>
    <child link="link2_sensor_6"/>
  </joint>
  <link name="link2_sensor_6">
  </link>
  <!-- sub-link defining detailed meshes for collision with environment -->
  <link name="fr3_link3">
    <visual name="fr3_link3_visual">
      <geometry>
        <mesh filename="package://gentact_descriptions/meshes/robot_arms/fr3/visual/link3.dae"/>
      </geometry>
    </visual>
    <collision name="fr3_link3_collision">
      <geometry>
        <mesh filename="package://gentact_descriptions/meshes/robot_arms/fr3/collision/link3.stl"/>
      </geometry>
    </collision>
    <inertial>
      <origin rpy="0 0 0" xyz="0.0407015686 -0.0048200565 -0.0289730823"/>
      <mass value="2.2449013699"/>
      <inertia ixx="0.02410142547240885" ixy="0.002404694559042109" ixz="-0.002856269270114313" iyy="0.01974053266708178" iyz="-0.002104212683891874" izz="0.019044494482244823"/>
    </inertial>
  </link>
  <joint name="fr3_joint3" type="revolute">
    <origin rpy="1.570796326794897 0 0" xyz="0 -0.316 0"/>
    <parent link="fr3_link2"/>
    <child link="fr3_link3"/>
    <axis xyz="0 0 1"/>
    <limit effort="87.0" lower="-2.9007" upper="2.9007" velocity="2.62"/>
    <safety_controller k_position="100.0" k_velocity="40.0" soft_lower_limit="-2.9007" soft_upper_limit="2.9007"/>
    <dynamics D="1" K="7000" damping="0.003" friction="0.2" mu_coulomb="0" mu_viscous="16"/>
  </joint>
  <!-- [m] -->
  <!-- Included URDF Files -->
  <link name="link3_skin">
    <visual>
      <origin rpy="0 0 0" xyz="0 0 0"/>
      <geometry>
        <!--loool the scale is totally different dude-->
        <mesh filename="package://gentact_descriptions/meshes/skin/hybrid/link3_hybrid_dermis.stl" scale="0.001 0.001 0.001"/>
      </geometry>
    </visual>
  </link>
  <joint name="link3_base_joint" type="fixed">
    <origin rpy="0 0 0" xyz="0 0 0"/>
    <parent link="fr3_link3"/>
    <child link="link3_skin"/>
  </joint>
  <!-- Instantiate sensors -->
  <joint name="link3_sensor_0_joint" type="fixed">
    <origin rpy="1.419 -0.000 -2.658" xyz="-0.025 0.052 -0.066"/>
    <axis xyz="0 0 0"/>
    <parent link="link3_skin"/>
    <child link="link3_sensor_0"/>
  </joint>
  <link name="link3_sensor_0">
  </link>
  <joint name="link3_sensor_1_joint" type="fixed">
    <origin rpy="1.838 -0.000 -2.747" xyz="0.057 0.110 -0.019"/>
    <axis xyz="0 0 0"/>
    <parent link="link3_skin"/>
    <child link="link3_sensor_1"/>
  </joint>
  <link name="link3_sensor_1">
  </link>
  <joint name="link3_sensor_2_joint" type="fixed">
    <origin rpy="1.410 0.000 2.306" xyz="0.124 0.101 0.009"/>
    <axis xyz="0 0 0"/>
    <parent link="link3_skin"/>
    <child link="link3_sensor_2"/>
  </joint>
  <link name="link3_sensor_2">
  </link>
  <joint name="link3_sensor_3_joint" type="fixed">
    <origin rpy="1.422 0.000 -1.108" xyz="-0.052 -0.026 -0.068"/>
    <axis xyz="0 0 0"/>
    <parent link="link3_skin"/>
    <child link="link3_sensor_3"/>
  </joint>
  <link name="link3_sensor_3">
  </link>
  <joint name="link3_sensor_4_joint" type="fixed">
    <origin rpy="0.800 0.000 -1.854" xyz="0.045 0.079 0.038"/>
    <axis xyz="0 0 0"/>
    <parent link="link3_skin"/>
    <child link="link3_sensor_4"/>
  </joint>
  <link name="link3_sensor_4">
  </link>
  <!-- sub-link defining detailed meshes for collision with environment -->
  <link name="fr3_link4">
    <visual name="fr3_link4_visual">
      <geometry>
        <mesh filename="package://gentact_descriptions/meshes/robot_arms/fr3/visual/link4.dae"/>
      </geometry>
    </visual>
    <collision name="fr3_link4_collision">
      <geometry>
        <mesh filename="package://gentact_descriptions/meshes/robot_arms/fr3/collision/link4.stl"/>
      </geometry>
    </collision>
    <inertial>
      <origin rpy="0 0 0" xyz="-0.0459100965 0.0630492960 -0.0085187868"/>
      <mass value="2.6155955791"/>
      <inertia ixx="0.03452998321913202" ixy="0.01322552265982813" ixz="0.01015142998484113" iyy="0.028881621933049058" iyz="-0.0009762833870704552" izz="0.04125471171146641"/>
    </inertial>
  </link>
  <joint name="fr3_joint4" type="revolute">
    <origin rpy="1.570796326794897 0 0" xyz="0.0825 0 0"/>
    <parent link="fr3_link3"/>
    <child link="fr3_link4"/>
    <axis xyz="0 0 1"/>
    <limit effort="87.0" lower="-3.0421" upper="-0.1518" velocity="2.62"/>
    <safety_controller k_position="100.0" k_velocity="40.0" soft_lower_limit="-3.0421" soft_upper_limit="-0.1518"/>
    <dynamics D="1" K="7000" damping="0.003" friction="0.2" mu_coulomb="0" mu_viscous="16"/>
  </joint>
  <!-- [m] -->
  <!-- Included URDF Files -->
  <link name="link4_skin">
    <visual>
      <origin rpy="0 0 0" xyz="0 0 0"/>
      <geometry>
        <!--loool the scale is totally different dude-->
        <mesh filename="package://gentact_descriptions/meshes/skin/hybrid/link4_hybrid_dermis.stl" scale="0.001 0.001 0.001"/>
      </geometry>
    </visual>
  </link>
  <joint name="link4_base_joint" type="fixed">
    <origin rpy="-1.5707 0 0" xyz="0 0 0"/>
    <parent link="fr3_link4"/>
    <child link="link4_skin"/>
  </joint>
  <!-- Instantiate sensors -->
  <joint name="link4_sensor_0_joint" type="fixed">
    <origin rpy="1.684 -0.000 -1.725" xyz="-0.141 0.008 0.079"/>
    <axis xyz="-0.982 0.152 -0.113"/>
    <parent link="link4_skin"/>
    <child link="link4_sensor_0"/>
  </joint>
  <link name="link4_sensor_0">
  </link>
  <joint name="link4_sensor_1_joint" type="fixed">
    <origin rpy="1.034 0.000 -0.180" xyz="-0.011 -0.108 0.033"/>
    <axis xyz="-0.154 -0.845 0.512"/>
    <parent link="link4_skin"/>
    <child link="link4_sensor_1"/>
  </joint>
  <link name="link4_sensor_1">
  </link>
  <joint name="link4_sensor_2_joint" type="fixed">
    <origin rpy="1.751 0.000 -0.355" xyz="-0.103 -0.052 0.058"/>
    <axis xyz="-0.342 -0.922 -0.179"/>
    <parent link="link4_skin"/>
    <child link="link4_sensor_2"/>
  </joint>
  <link name="link4_sensor_2">
  </link>
  <joint name="link4_sensor_3_joint" type="fixed">
    <origin rpy="1.554 0.000 0.829" xyz="0.043 -0.101 0.003"/>
    <axis xyz="0.737 -0.676 0.017"/>
    <parent link="link4_skin"/>
    <child link="link4_sensor_3"/>
  </joint>
  <link name="link4_sensor_3">
  </link>
  <joint name="link4_sensor_4_joint" type="fixed">
    <origin rpy="1.946 0.000 -0.056" xyz="-0.004 -0.113 -0.025"/>
    <axis xyz="-0.052 -0.929 -0.367"/>
    <parent link="link4_skin"/>
    <child link="link4_sensor_4"/>
  </joint>
  <link name="link4_sensor_4">
  </link>
  <!-- sub-link defining detailed meshes for collision with environment -->
  <link name="fr3_link5">
    <visual name="fr3_link5_visual">
      <geometry>
        <mesh filename="package://gentact_descriptions/meshes/robot_arms/fr3/visual/link5.dae"/>
      </geometry>
    </visual>
    <collision name="fr3_link5_collision">
      <geometry>
        <mesh filename="package://gentact_descriptions/meshes/robot_arms/fr3/collision/link5.stl"/>
      </geometry>
    </collision>
    <inertial>
      <origin rpy="0 0 0" xyz="-0.0016039605 0.0292536262 -0.0972965990"/>
      <mass value="2.3271207594"/>
      <inertia ixx="0.051610278463662895" ixy="-0.005715173387783472" ixz="-0.0035673167625872135" iyy="0.04787729713371481" iyz="0.010673985108535986" izz="0.016423625579357254"/>
    </inertial>
  </link>
  <joint name="fr3_joint5" type="revolute">
    <origin rpy="-1.570796326794897 0 0" xyz="-0.0825 0.384 0"/>
    <parent link="fr3_link4"/>
    <child link="fr3_link5"/>
    <axis xyz="0 0 1"/>
    <limit effort="12.0" lower="-2.8065" upper="2.8065" velocity="5.26"/>
    <safety_controller k_position="100.0" k_velocity="40.0" soft_lower_limit="-2.8065" soft_upper_limit="2.8065"/>
    <dynamics D="1" K="7000" damping="0.003" friction="0.2" mu_coulomb="0" mu_viscous="16"/>
  </joint>
  <!-- [m] -->
  <link name="link5_front_skin">
    <visual>
      <origin rpy="0 0 0" xyz="0 0 0"/>
      <geometry>
        <!--loool the scale is totally different dude-->
        <mesh filename="package://gentact_descriptions/meshes/skin/hybrid/link5_part1_hybrid_dermis.stl" scale="0.001 0.001 0.001"/>
      </geometry>
    </visual>
  </link>
  <joint name="link5_front_base_joint" type="fixed">
    <origin rpy="0 0 0" xyz="0 0 0"/>
    <parent link="fr3_link5"/>
    <child link="link5_front_skin"/>
  </joint>
  <!-- Instantiate sensors -->
  <joint name="link5_front_sensor_0_joint" type="fixed">
    <origin rpy="0.896 0.000 -0.487" xyz="-0.025 -0.042 -0.191"/>
    <axis xyz="0 0 0"/>
    <parent link="link5_front_skin"/>
    <child link="link5_front_sensor_0"/>
  </joint>
  <link name="link5_front_sensor_0">
  </link>
  <joint name="link5_front_sensor_1_joint" type="fixed">
    <origin rpy="0.394 0.000 -0.062" xyz="-0.002 0.022 -0.152"/>
    <axis xyz="0 0 0"/>
    <parent link="link5_front_skin"/>
    <child link="link5_front_sensor_1"/>
  </joint>
  <link name="link5_front_sensor_1">
  </link>
  <joint name="link5_front_sensor_2_joint" type="fixed">
    <origin rpy="1.380 -0.000 -0.028" xyz="-0.000 0.058 -0.115"/>
    <axis xyz="0 0 0"/>
    <parent link="link5_front_skin"/>
    <child link="link5_front_sensor_2"/>
  </joint>
  <link name="link5_front_sensor_2">
  </link>
  <joint name="link5_front_sensor_3_joint" type="fixed">
    <origin rpy="0.901 -0.000 0.501" xyz="0.027 -0.041 -0.191"/>
    <axis xyz="0 0 0"/>
    <parent link="link5_front_skin"/>
    <child link="link5_front_sensor_3"/>
  </joint>
  <link name="link5_front_sensor_3">
  </link>
  <!-- [m] -->
  <!-- Included URDF Files -->
  <link name="link5_back_skin">
    <visual>
      <origin rpy="0 0 0" xyz="0 0 0"/>
      <geometry>
        <!--loool the scale is totally different dude-->
        <mesh filename="package://gentact_descriptions/meshes/skin/hybrid/link5_part2_hybrid_dermis.stl" scale="0.001 0.001 0.001"/>
      </geometry>
    </visual>
  </link>
  <joint name="link5_back_base_joint" type="fixed">
    <origin rpy="0 0 0" xyz="0 0 0"/>
    <parent link="fr3_link5"/>
    <child link="link5_back_skin"/>
  </joint>
  <!-- Instantiate sensors -->
  <joint name="link5_back_sensor_0_joint" type="fixed">
    <origin rpy="-1.397 -3.142 0.049" xyz="-0.006 0.114 -0.097"/>
    <axis xyz="-0.048 0.984 -0.173"/>
    <parent link="link5_back_skin"/>
    <child link="link5_back_sensor_0"/>
  </joint>
  <link name="link5_back_sensor_0">
  </link>
  <joint name="link5_back_sensor_1_joint" type="fixed">
    <origin rpy="1.754 0.000 -2.751" xyz="-0.021 0.102 -0.151"/>
    <axis xyz="-0.374 0.909 -0.182"/>
    <parent link="link5_back_skin"/>
    <child link="link5_back_sensor_1"/>
  </joint>
  <link name="link5_back_sensor_1">
  </link>
  <joint name="link5_back_sensor_2_joint" type="fixed">
    <origin rpy="-1.337 3.142 0.049" xyz="-0.002 0.135 -0.018"/>
    <axis xyz="-0.048 0.972 -0.232"/>
    <parent link="link5_back_skin"/>
    <child link="link5_back_sensor_2"/>
  </joint>
  <link name="link5_back_sensor_2">
  </link>
  <joint name="link5_back_sensor_3_joint" type="fixed">
    <origin rpy="1.758 -0.000 2.749" xyz="0.020 0.103 -0.148"/>
    <axis xyz="0.376 0.908 -0.187"/>
    <parent link="link5_back_skin"/>
    <child link="link5_back_sensor_3"/>
  </joint>
  <link name="link5_back_sensor_3">
  </link>
  <joint name="link5_back_sensor_4_joint" type="fixed">
    <origin rpy="1.278 0.000 2.016" xyz="0.049 0.108 0.014"/>
    <axis xyz="0.864 0.412 0.289"/>
    <parent link="link5_back_skin"/>
    <child link="link5_back_sensor_4"/>
  </joint>
  <link name="link5_back_sensor_4">
  </link>
  <joint name="link5_back_sensor_5_joint" type="fixed">
    <origin rpy="1.282 0.000 -2.017" xyz="-0.050 0.106 0.016"/>
    <axis xyz="-0.865 0.414 0.285"/>
    <parent link="link5_back_skin"/>
    <child link="link5_back_sensor_5"/>
  </joint>
  <link name="link5_back_sensor_5">
  </link>
  <!-- sub-link defining detailed meshes for collision with environment -->
  <link name="fr3_link6">
    <visual name="fr3_link6_visual">
      <geometry>
        <mesh filename="package://gentact_descriptions/meshes/robot_arms/fr3/visual/link6.dae"/>
      </geometry>
    </visual>
    <collision name="fr3_link6_collision">
      <geometry>
        <mesh filename="package://gentact_descriptions/meshes/robot_arms/fr3/collision/link6.stl"/>
      </geometry>
    </collision>
    <inertial>
      <origin rpy="0 0 0" xyz="0.0597131221 -0.0410294666 -0.0101692726"/>
      <mass value="1.8170376524"/>
      <inertia ixx="0.005412333594383447" ixy="0.006193456360285834" ixz="0.0014219289306117652" iyy="0.014058329545509979" iyz="-0.0013140753741120031" izz="0.016080817924212554"/>
    </inertial>
  </link>
  <joint name="fr3_joint6" type="revolute">
    <origin rpy="1.570796326794897 0 0" xyz="0 0 0"/>
    <parent link="fr3_link5"/>
    <child link="fr3_link6"/>
    <axis xyz="0 0 1"/>
    <limit effort="12.0" lower="0.5445" upper="4.5169" velocity="4.18"/>
    <safety_controller k_position="100.0" k_velocity="40.0" soft_lower_limit="0.5445" soft_upper_limit="4.5169"/>
    <dynamics D="1" K="7000" damping="0.003" friction="0.2" mu_coulomb="0" mu_viscous="16"/>
  </joint>
  <!-- [m] -->
  <!-- Included URDF Files -->
  <link name="link6_skin">
    <visual>
      <origin rpy="0 0 0" xyz="0 0 0"/>
      <geometry>
        <!--loool the scale is totally different dude-->
        <mesh filename="package://gentact_descriptions/meshes/skin/hybrid/link6_hybrid_dermis.stl" scale="0.001 0.001 0.001"/>
      </geometry>
    </visual>
  </link>
  <joint name="link6_base_joint" type="fixed">
    <origin rpy="-1.5707 0 0" xyz="0 0 0"/>
    <parent link="fr3_link6"/>
    <child link="link6_skin"/>
  </joint>
  <joint name="link6_sensor_0_joint" type="fixed">
    <origin rpy="1.530 0.000 0.234" xyz="0.087 -0.053 0.008"/>
    <axis xyz="0.232 -0.972 0.041"/>
    <parent link="link6_skin"/>
    <child link="link6_sensor_0"/>
  </joint>
  <link name="link6_sensor_0">
  </link>
  <joint name="link6_sensor_1_joint" type="fixed">
    <origin rpy="0.850 0.000 -0.306" xyz="-0.012 -0.050 0.038"/>
    <axis xyz="-0.226 -0.717 0.66"/>
    <parent link="link6_skin"/>
    <child link="link6_sensor_1"/>
  </joint>
  <link name="link6_sensor_1">
  </link>
  <joint name="link6_sensor_2_joint" type="fixed">
    <origin rpy="1.595 0.000 -0.018" xyz="0.027 -0.064 0.008"/>
    <axis xyz="-0.018 -1.0 -0.024"/>
    <parent link="link6_skin"/>
    <child link="link6_sensor_2"/>
  </joint>
  <link name="link6_sensor_2">
  </link>
  <joint name="link6_sensor_3_joint" type="fixed">
    <origin rpy="1.552 -0.000 2.718" xyz="0.110 0.047 0.009"/>
    <axis xyz="0.411 0.912 0.019"/>
    <parent link="link6_skin"/>
    <child link="link6_sensor_3"/>
  </joint>
  <link name="link6_sensor_3">
  </link>
  <joint name="link6_sensor_4_joint" type="fixed">
    <origin rpy="1.556 0.000 1.098" xyz="0.134 -0.022 0.007"/>
    <axis xyz="0.89 -0.455 0.015"/>
    <parent link="link6_skin"/>
    <child link="link6_sensor_4"/>
  </joint>
  <link name="link6_sensor_4">
  </link>
  <joint name="link6_sensor_5_joint" type="fixed">
    <origin rpy="1.726 -0.000 -0.675" xyz="-0.031 -0.054 -0.011"/>
    <axis xyz="-0.618 -0.771 -0.155"/>
    <parent link="link6_skin"/>
    <child link="link6_sensor_5"/>
  </joint>
  <link name="link6_sensor_5">
  </link>
  <!-- sub-link defining detailed meshes for collision with environment -->
  <link name="fr3_link7">
    <visual name="fr3_link7_visual">
      <geometry>
        <mesh filename="package://gentact_descriptions/meshes/robot_arms/fr3/visual/link7.dae"/>
      </geometry>
    </visual>
    <collision name="fr3_link7_collision">
      <geometry>
        <mesh filename="package://gentact_descriptions/meshes/robot_arms/fr3/collision/link7.stl"/>
      </geometry>
    </collision>
    <inertial>
      <origin rpy="0 0 0" xyz="0.0045225817 0.0086261921 -0.0161633251"/>
      <mass value="0.6271432862"/>
      <inertia ixx="0.00021092389150104718" ixy="-2.433299114461931e-05" ixz="4.564480393778983e-05" iyy="0.00017718568002411474" iyz="8.744070223226438e-05" izz="5.993190599659971e-05"/>
    </inertial>
  </link>
  <joint name="fr3_joint7" type="revolute">
    <origin rpy="1.570796326794897 0 0" xyz="0.088 0 0"/>
    <parent link="fr3_link6"/>
    <child link="fr3_link7"/>
    <axis xyz="0 0 1"/>
    <limit effort="12.0" lower="-3.0159" upper="3.0159" velocity="5.26"/>
    <safety_controller k_position="100.0" k_velocity="40.0" soft_lower_limit="-3.0159" soft_upper_limit="3.0159"/>
    <dynamics D="1" K="7000" damping="0.003" friction="0.2" mu_coulomb="0" mu_viscous="16"/>
  </joint>
  <link name="fr3_link8"/>
  <joint name="fr3_joint8" type="fixed">
    <origin rpy="0 0 0" xyz="0 0 0.107"/>
    <parent link="fr3_link7"/>
    <child link="fr3_link8"/>
  </joint>
  <joint name="fr3_hand_joint" type="fixed">
    <parent link="fr3_link8"/>
    <child link="fr3_hand"/>
    <origin rpy="0 0 -0.7853981633974483" xyz="0 0 0"/>
  </joint>
  <!-- sub-link defining detailed meshes for collision with environment -->
  <link name="fr3_hand">
    <visual name="fr3_hand_visual">
      <geometry>
        <mesh filename="package://gentact_descriptions/meshes/robot_ee/franka_hand_white/visual/hand.dae"/>
      </geometry>
    </visual>
    <collision name="fr3_hand_collision">
      <geometry>
        <mesh filename="package://gentact_descriptions/meshes/robot_ee/franka_hand_white/collision/hand.stl"/>
      </geometry>
    </collision>
    <inertial>
      <origin rpy="0 0 0" xyz="-0.0000376 0.0119128 0.0207260"/>
      <mass value="0.6544"/>
      <inertia ixx="0.00186" ixy="0.0" ixz="0.0" iyy="0.0003" iyz="-2e-05" izz="0.00174"/>
    </inertial>
  </link>
  <!-- Define the hand_tcp frame -->
  <link name="fr3_hand_tcp"/>
  <joint name="fr3_hand_tcp_joint" type="fixed">
    <origin rpy="0 0 0" xyz="0 0 0.1034"/>
    <parent link="fr3_hand"/>
    <child link="fr3_hand_tcp"/>
  </joint>
  <link name="fr3_leftfinger">
    <visual name="fr3_leftfinger_visual">
      <geometry>
        <mesh filename="package://gentact_descriptions/meshes/robot_ee/franka_hand_white/visual/finger.dae"/>
      </geometry>
    </visual>
    <!-- screw mount -->
    <collision>
      <origin rpy="0 0 0" xyz="0 18.5e-3 11e-3"/>
      <geometry>
        <box size="22e-3 15e-3 20e-3"/>
      </geometry>
    </collision>
    <!-- cartriage sledge -->
    <collision>
      <origin rpy="0 0 0" xyz="0 6.8e-3 2.2e-3"/>
      <geometry>
        <box size="22e-3 8.8e-3 3.8e-3"/>
      </geometry>
    </collision>
    <!-- diagonal finger -->
    <collision>
      <origin rpy="0.5235987755982988 0 0" xyz="0 15.9e-3 28.35e-3"/>
      <geometry>
        <box size="17.5e-3 7e-3 23.5e-3"/>
      </geometry>
    </collision>
    <!-- rubber tip with which to grasp -->
    <collision>
      <origin rpy="0 0 0" xyz="0 7.58e-3 45.25e-3"/>
      <geometry>
        <box size="17.5e-3 15.2e-3 18.5e-3"/>
      </geometry>
    </collision>
    <inertial>
      <origin rpy="0 0 0" xyz="0 0.0152850 0.0219675"/>
      <mass value="0.0291"/>
      <inertia ixx="8.49e-06" ixy="0.0" ixz="0.0" iyy="8.53e-06" iyz="-1.06e-06" izz="1.77e-06"/>
    </inertial>
  </link>
  <link name="fr3_rightfinger">
    <visual name="fr3_rightfinger_visual">
      <origin rpy="0 0 0" xyz="0 0 0"/>
      <geometry>
        <mesh filename="package://gentact_descriptions/meshes/robot_ee/franka_hand_white/visual/finger.dae"/>
      </geometry>
    </visual>
    <!-- screw mount -->
    <collision>
      <origin rpy="0 0 0" xyz="0 18.5e-3 11e-3"/>
      <geometry>
        <box size="22e-3 15e-3 20e-3"/>
      </geometry>
    </collision>
    <!-- cartriage sledge -->
    <collision>
      <origin rpy="0 0 0" xyz="0 6.8e-3 2.2e-3"/>
      <geometry>
        <box size="22e-3 8.8e-3 3.8e-3"/>
      </geometry>
    </collision>
    <!-- diagonal finger -->
    <collision>
      <origin rpy="-0.5235987755982988 0 3.141592653589793" xyz="0 15.9e-3 28.35e-3"/>
      <geometry>
        <box size="17.5e-3 7e-3 23.5e-3"/>
      </geometry>
    </collision>
    <!-- rubber tip with which to grasp -->
    <collision>
      <origin rpy="0 0 0" xyz="0 7.58e-3 45.25e-3"/>
      <geometry>
        <box size="17.5e-3 15.2e-3 18.5e-3"/>
      </geometry>
    </collision>
    <inertial>
      <origin rpy="0 0 0" xyz="0 0.0152850 0.0219675"/>
      <mass value="0.0291"/>
      <inertia ixx="8.49e-06" ixy="0.0" ixz="0.0" iyy="8.53e-06" iyz="-1.06e-06" izz="1.77e-06"/>
    </inertial>
  </link>
  <joint name="fr3_finger_joint1" type="prismatic">
    <parent link="fr3_hand"/>
    <child link="fr3_leftfinger"/>
    <origin rpy="0 0 0" xyz="0 0 0.0584"/>
    <axis xyz="0 1 0"/>
    <limit effort="100" lower="0.0" upper="0.04" velocity="0.2"/>
    <dynamics damping="0.3"/>
  </joint>
  <joint name="fr3_finger_joint2" type="prismatic">
    <parent link="fr3_hand"/>
    <child link="fr3_rightfinger"/>
    <origin rpy="0 0 3.141592653589793" xyz="0 0 0.0584"/>
    <axis xyz="0 1 0"/>
    <limit effort="100" lower="0.0" upper="0.04" velocity="0.2"/>
    <mimic joint="fr3_finger_joint1"/>
    <dynamics damping="0.3"/>
  </joint>
</robot>
